# Error Handling in JavaScript

An error in JavaScript signifies an abnormal condition that disrupts the normal flow of execution. This can happen due to a variety of reasons, such as invalid user input, network failures, or developer mistakes. When such a condition arises, JavaScript creates and throws an Error object.An Error object in JavaScript is an instance of the Error constructor. It includes properties like 'name', which provides the general class of Error (such as DOMException or Error), and 'message', which usually provides a more succinct message about the error.

```javascript
const err = new Error("Something bad happened!");
```

## Try-Catch-Finally

JavaScript provides a set of keywords to handle errors: 'try', 'catch', and 'finally'. The 'try' block contains the code that might throw an exception. The 'catch' block contains the code to handle the error if one occurs in the 'try' block. The 'finally' block contains the code that will be executed regardless of whether an error was thrown or caught.

```javascript
try {
  // Code that might throw an error
} catch (err) {
  // Handle the error
  console.error(err.message);
} finally {
  // This code runs regardless of whether an error occurred
}

```

## Throwing Custom Errors

In addition to the built-in Error objects, JavaScript allows developers to throw their own custom errors. This can be particularly useful when you want to provide more specific error messages or handle certain types of errors differently.


```javascript
function doSomethingErrorProne() {
  if (ourCodeMakesAMistake()) {
    throw new Error("Custom error message");
  } else {
    doSomethingToGetAJavaScriptError();
  }
}
```


## Asynchronous Error Handling

Promises and async/await are commonly used patterns for handling errors in asynchronous code. With promises, you can use the 'then' method for resolving the promise and 'catch' method for handling any errors. With async/await, you can use the try/catch block just like with synchronous code.

```javascript
// With Promises
doSomethingAsync()
  .then(result => console.log(result))
  .catch(err => console.error(err));

// With async/await
async function doSomething() {
  try {
    const result = await doSomethingAsync();
    console.log(result);
  } catch (err) {
    console.error(err);
  }
}
```